Falling back to TensorFlow client; we recommended you install the Cloud TPU client directly with pip install cloud-tpu-client.
Creating converter from 7 to 5
Creating converter from 5 to 7
Creating converter from 7 to 5
Creating converter from 5 to 7
Creating converter from 3 to 5
No training configuration found in the save file, so the model was *not* compiled. Compile it manually.
Falling back to TensorFlow client; we recommended you install the Cloud TPU client directly with pip install cloud-tpu-client.
Creating converter from 7 to 5
Creating converter from 5 to 7
Creating converter from 7 to 5
Creating converter from 5 to 7
Creating converter from 3 to 5
No training configuration found in the save file, so the model was *not* compiled. Compile it manually.
Falling back to TensorFlow client; we recommended you install the Cloud TPU client directly with pip install cloud-tpu-client.
Creating converter from 7 to 5
Creating converter from 5 to 7
Creating converter from 7 to 5
Creating converter from 5 to 7
Creating converter from 3 to 5
No training configuration found in the save file, so the model was *not* compiled. Compile it manually.
Falling back to TensorFlow client; we recommended you install the Cloud TPU client directly with pip install cloud-tpu-client.
Creating converter from 7 to 5
Creating converter from 5 to 7
Creating converter from 7 to 5
Creating converter from 5 to 7
Creating converter from 3 to 5
No training configuration found in the save file, so the model was *not* compiled. Compile it manually.
Falling back to TensorFlow client; we recommended you install the Cloud TPU client directly with pip install cloud-tpu-client.
Creating converter from 7 to 5
Creating converter from 5 to 7
Creating converter from 7 to 5
Creating converter from 5 to 7
Creating converter from 3 to 5
No training configuration found in the save file, so the model was *not* compiled. Compile it manually.
Falling back to TensorFlow client; we recommended you install the Cloud TPU client directly with pip install cloud-tpu-client.
Creating converter from 7 to 5
Creating converter from 5 to 7
Creating converter from 7 to 5
Creating converter from 5 to 7
Creating converter from 3 to 5
No training configuration found in the save file, so the model was *not* compiled. Compile it manually.
Watching for file changes with StatReloader
Importing BlpImagePlugin
Importing BmpImagePlugin
Importing BufrStubImagePlugin
Importing CurImagePlugin
Importing DcxImagePlugin
Importing DdsImagePlugin
Importing EpsImagePlugin
Importing FitsImagePlugin
Importing FliImagePlugin
Importing FpxImagePlugin
Image: failed to import FpxImagePlugin: No module named 'olefile'
Importing FtexImagePlugin
Importing GbrImagePlugin
Importing GifImagePlugin
Importing GribStubImagePlugin
Importing Hdf5StubImagePlugin
Importing IcnsImagePlugin
Importing IcoImagePlugin
Importing ImImagePlugin
Importing ImtImagePlugin
Importing IptcImagePlugin
Importing JpegImagePlugin
Importing Jpeg2KImagePlugin
Importing McIdasImagePlugin
Importing MicImagePlugin
Image: failed to import MicImagePlugin: No module named 'olefile'
Importing MpegImagePlugin
Importing MpoImagePlugin
Importing MspImagePlugin
Importing PalmImagePlugin
Importing PcdImagePlugin
Importing PcxImagePlugin
Importing PdfImagePlugin
Importing PixarImagePlugin
Importing PngImagePlugin
Importing PpmImagePlugin
Importing PsdImagePlugin
Importing QoiImagePlugin
Importing SgiImagePlugin
Importing SpiderImagePlugin
Importing SunImagePlugin
Importing TgaImagePlugin
Importing TiffImagePlugin
Importing WebPImagePlugin
Importing WmfImagePlugin
Importing XbmImagePlugin
Importing XpmImagePlugin
Importing XVThumbImagePlugin
Falling back to TensorFlow client; we recommended you install the Cloud TPU client directly with pip install cloud-tpu-client.
Creating converter from 7 to 5
Creating converter from 5 to 7
Creating converter from 7 to 5
Creating converter from 5 to 7
Creating converter from 3 to 5
No training configuration found in the save file, so the model was *not* compiled. Compile it manually.
Falling back to TensorFlow client; we recommended you install the Cloud TPU client directly with pip install cloud-tpu-client.
Creating converter from 7 to 5
Creating converter from 5 to 7
Creating converter from 7 to 5
Creating converter from 5 to 7
Creating converter from 3 to 5
No training configuration found in the save file, so the model was *not* compiled. Compile it manually.
Watching for file changes with StatReloader
Internal Server Error: /accounts/login/
Traceback (most recent call last):
  File "C:\Users\lhu07\anaconda3\envs\big_project\Lib\site-packages\django\core\handlers\exception.py", line 55, in inner
    response = get_response(request)
               ^^^^^^^^^^^^^^^^^^^^^
  File "C:\Users\lhu07\anaconda3\envs\big_project\Lib\site-packages\django\core\handlers\base.py", line 220, in _get_response
    response = response.render()
               ^^^^^^^^^^^^^^^^^
  File "C:\Users\lhu07\anaconda3\envs\big_project\Lib\site-packages\django\template\response.py", line 114, in render
    self.content = self.rendered_content
                   ^^^^^^^^^^^^^^^^^^^^^
  File "C:\Users\lhu07\anaconda3\envs\big_project\Lib\site-packages\django\template\response.py", line 90, in rendered_content
    template = self.resolve_template(self.template_name)
               ^^^^^^^^^^^^^^^^^^^^^^^^^^^^^^^^^^^^^^^^^
  File "C:\Users\lhu07\anaconda3\envs\big_project\Lib\site-packages\django\template\response.py", line 72, in resolve_template
    return select_template(template, using=self.using)
           ^^^^^^^^^^^^^^^^^^^^^^^^^^^^^^^^^^^^^^^^^^^
  File "C:\Users\lhu07\anaconda3\envs\big_project\Lib\site-packages\django\template\loader.py", line 47, in select_template
    raise TemplateDoesNotExist(", ".join(template_name_list), chain=chain)
django.template.exceptions.TemplateDoesNotExist: registration/login.html
E:\빅프로젝트_34조\be_detect\bigproject28-1\aivle_big\urls.py changed, reloading.
Falling back to TensorFlow client; we recommended you install the Cloud TPU client directly with pip install cloud-tpu-client.
Creating converter from 7 to 5
Creating converter from 5 to 7
Creating converter from 7 to 5
Creating converter from 5 to 7
Creating converter from 3 to 5
No training configuration found in the save file, so the model was *not* compiled. Compile it manually.
Watching for file changes with StatReloader
Internal Server Error: /accounts/login/
Traceback (most recent call last):
  File "C:\Users\lhu07\anaconda3\envs\big_project\Lib\site-packages\django\core\handlers\exception.py", line 55, in inner
    response = get_response(request)
               ^^^^^^^^^^^^^^^^^^^^^
  File "C:\Users\lhu07\anaconda3\envs\big_project\Lib\site-packages\django\core\handlers\base.py", line 220, in _get_response
    response = response.render()
               ^^^^^^^^^^^^^^^^^
  File "C:\Users\lhu07\anaconda3\envs\big_project\Lib\site-packages\django\template\response.py", line 114, in render
    self.content = self.rendered_content
                   ^^^^^^^^^^^^^^^^^^^^^
  File "C:\Users\lhu07\anaconda3\envs\big_project\Lib\site-packages\django\template\response.py", line 90, in rendered_content
    template = self.resolve_template(self.template_name)
               ^^^^^^^^^^^^^^^^^^^^^^^^^^^^^^^^^^^^^^^^^
  File "C:\Users\lhu07\anaconda3\envs\big_project\Lib\site-packages\django\template\response.py", line 72, in resolve_template
    return select_template(template, using=self.using)
           ^^^^^^^^^^^^^^^^^^^^^^^^^^^^^^^^^^^^^^^^^^^
  File "C:\Users\lhu07\anaconda3\envs\big_project\Lib\site-packages\django\template\loader.py", line 47, in select_template
    raise TemplateDoesNotExist(", ".join(template_name_list), chain=chain)
django.template.exceptions.TemplateDoesNotExist: registration/login.html
Internal Server Error: /accounts/login/
Traceback (most recent call last):
  File "C:\Users\lhu07\anaconda3\envs\big_project\Lib\site-packages\django\core\handlers\exception.py", line 55, in inner
    response = get_response(request)
               ^^^^^^^^^^^^^^^^^^^^^
  File "C:\Users\lhu07\anaconda3\envs\big_project\Lib\site-packages\django\core\handlers\base.py", line 220, in _get_response
    response = response.render()
               ^^^^^^^^^^^^^^^^^
  File "C:\Users\lhu07\anaconda3\envs\big_project\Lib\site-packages\django\template\response.py", line 114, in render
    self.content = self.rendered_content
                   ^^^^^^^^^^^^^^^^^^^^^
  File "C:\Users\lhu07\anaconda3\envs\big_project\Lib\site-packages\django\template\response.py", line 90, in rendered_content
    template = self.resolve_template(self.template_name)
               ^^^^^^^^^^^^^^^^^^^^^^^^^^^^^^^^^^^^^^^^^
  File "C:\Users\lhu07\anaconda3\envs\big_project\Lib\site-packages\django\template\response.py", line 72, in resolve_template
    return select_template(template, using=self.using)
           ^^^^^^^^^^^^^^^^^^^^^^^^^^^^^^^^^^^^^^^^^^^
  File "C:\Users\lhu07\anaconda3\envs\big_project\Lib\site-packages\django\template\loader.py", line 47, in select_template
    raise TemplateDoesNotExist(", ".join(template_name_list), chain=chain)
django.template.exceptions.TemplateDoesNotExist: registration/login.html
Internal Server Error: /accounts/login/
Traceback (most recent call last):
  File "C:\Users\lhu07\anaconda3\envs\big_project\Lib\site-packages\django\core\handlers\exception.py", line 55, in inner
    response = get_response(request)
               ^^^^^^^^^^^^^^^^^^^^^
  File "C:\Users\lhu07\anaconda3\envs\big_project\Lib\site-packages\django\core\handlers\base.py", line 220, in _get_response
    response = response.render()
               ^^^^^^^^^^^^^^^^^
  File "C:\Users\lhu07\anaconda3\envs\big_project\Lib\site-packages\django\template\response.py", line 114, in render
    self.content = self.rendered_content
                   ^^^^^^^^^^^^^^^^^^^^^
  File "C:\Users\lhu07\anaconda3\envs\big_project\Lib\site-packages\django\template\response.py", line 90, in rendered_content
    template = self.resolve_template(self.template_name)
               ^^^^^^^^^^^^^^^^^^^^^^^^^^^^^^^^^^^^^^^^^
  File "C:\Users\lhu07\anaconda3\envs\big_project\Lib\site-packages\django\template\response.py", line 72, in resolve_template
    return select_template(template, using=self.using)
           ^^^^^^^^^^^^^^^^^^^^^^^^^^^^^^^^^^^^^^^^^^^
  File "C:\Users\lhu07\anaconda3\envs\big_project\Lib\site-packages\django\template\loader.py", line 47, in select_template
    raise TemplateDoesNotExist(", ".join(template_name_list), chain=chain)
django.template.exceptions.TemplateDoesNotExist: registration/login.html
Internal Server Error: /login/login/
Traceback (most recent call last):
  File "C:\Users\lhu07\anaconda3\envs\big_project\Lib\site-packages\django\urls\base.py", line 71, in reverse
    extra, resolver = resolver.namespace_dict[ns]
                      ~~~~~~~~~~~~~~~~~~~~~~~^^^^
KeyError: 'community'

During handling of the above exception, another exception occurred:

Traceback (most recent call last):
  File "C:\Users\lhu07\anaconda3\envs\big_project\Lib\site-packages\django\core\handlers\exception.py", line 55, in inner
    response = get_response(request)
               ^^^^^^^^^^^^^^^^^^^^^
  File "C:\Users\lhu07\anaconda3\envs\big_project\Lib\site-packages\django\core\handlers\base.py", line 197, in _get_response
    response = wrapped_callback(request, *callback_args, **callback_kwargs)
               ^^^^^^^^^^^^^^^^^^^^^^^^^^^^^^^^^^^^^^^^^^^^^^^^^^^^^^^^^^^^
  File "C:\Users\lhu07\anaconda3\envs\big_project\Lib\site-packages\django\views\decorators\csrf.py", line 65, in _view_wrapper
    return view_func(request, *args, **kwargs)
           ^^^^^^^^^^^^^^^^^^^^^^^^^^^^^^^^^^^
  File "E:\빅프로젝트_34조\be_detect\bigproject28-1\login\views.py", line 54, in login
    return render(request, 'login.html')
           ^^^^^^^^^^^^^^^^^^^^^^^^^^^^^
  File "C:\Users\lhu07\anaconda3\envs\big_project\Lib\site-packages\django\shortcuts.py", line 25, in render
    content = loader.render_to_string(template_name, context, request, using=using)
              ^^^^^^^^^^^^^^^^^^^^^^^^^^^^^^^^^^^^^^^^^^^^^^^^^^^^^^^^^^^^^^^^^^^^^
  File "C:\Users\lhu07\anaconda3\envs\big_project\Lib\site-packages\django\template\loader.py", line 62, in render_to_string
    return template.render(context, request)
           ^^^^^^^^^^^^^^^^^^^^^^^^^^^^^^^^^
  File "C:\Users\lhu07\anaconda3\envs\big_project\Lib\site-packages\django\template\backends\django.py", line 61, in render
    return self.template.render(context)
           ^^^^^^^^^^^^^^^^^^^^^^^^^^^^^
  File "C:\Users\lhu07\anaconda3\envs\big_project\Lib\site-packages\django\template\base.py", line 171, in render
    return self._render(context)
           ^^^^^^^^^^^^^^^^^^^^^
  File "C:\Users\lhu07\anaconda3\envs\big_project\Lib\site-packages\django\template\base.py", line 163, in _render
    return self.nodelist.render(context)
           ^^^^^^^^^^^^^^^^^^^^^^^^^^^^^
  File "C:\Users\lhu07\anaconda3\envs\big_project\Lib\site-packages\django\template\base.py", line 1000, in render
    return SafeString("".join([node.render_annotated(context) for node in self]))
                              ^^^^^^^^^^^^^^^^^^^^^^^^^^^^^^^^^^^^^^^^^^^^^^^^^
  File "C:\Users\lhu07\anaconda3\envs\big_project\Lib\site-packages\django\template\base.py", line 1000, in <listcomp>
    return SafeString("".join([node.render_annotated(context) for node in self]))
                               ^^^^^^^^^^^^^^^^^^^^^^^^^^^^^^
  File "C:\Users\lhu07\anaconda3\envs\big_project\Lib\site-packages\django\template\base.py", line 961, in render_annotated
    return self.render(context)
           ^^^^^^^^^^^^^^^^^^^^
  File "C:\Users\lhu07\anaconda3\envs\big_project\Lib\site-packages\django\template\defaulttags.py", line 479, in render
    url = reverse(view_name, args=args, kwargs=kwargs, current_app=current_app)
          ^^^^^^^^^^^^^^^^^^^^^^^^^^^^^^^^^^^^^^^^^^^^^^^^^^^^^^^^^^^^^^^^^^^^^
  File "C:\Users\lhu07\anaconda3\envs\big_project\Lib\site-packages\django\urls\base.py", line 82, in reverse
    raise NoReverseMatch("%s is not a registered namespace" % key)
django.urls.exceptions.NoReverseMatch: 'community' is not a registered namespace
E:\빅프로젝트_34조\be_detect\bigproject28-1\aivle_big\urls.py changed, reloading.
Falling back to TensorFlow client; we recommended you install the Cloud TPU client directly with pip install cloud-tpu-client.
Creating converter from 7 to 5
Creating converter from 5 to 7
Creating converter from 7 to 5
Creating converter from 5 to 7
Creating converter from 3 to 5
No training configuration found in the save file, so the model was *not* compiled. Compile it manually.
Watching for file changes with StatReloader
E:\빅프로젝트_34조\be_detect\bigproject28-1\detect\models.py changed, reloading.
Falling back to TensorFlow client; we recommended you install the Cloud TPU client directly with pip install cloud-tpu-client.
Creating converter from 7 to 5
Creating converter from 5 to 7
Creating converter from 7 to 5
Creating converter from 5 to 7
Creating converter from 3 to 5
No training configuration found in the save file, so the model was *not* compiled. Compile it manually.
Falling back to TensorFlow client; we recommended you install the Cloud TPU client directly with pip install cloud-tpu-client.
Creating converter from 7 to 5
Creating converter from 5 to 7
Creating converter from 7 to 5
Creating converter from 5 to 7
Creating converter from 3 to 5
No training configuration found in the save file, so the model was *not* compiled. Compile it manually.
Falling back to TensorFlow client; we recommended you install the Cloud TPU client directly with pip install cloud-tpu-client.
Creating converter from 7 to 5
Creating converter from 5 to 7
Creating converter from 7 to 5
Creating converter from 5 to 7
Creating converter from 3 to 5
No training configuration found in the save file, so the model was *not* compiled. Compile it manually.
Falling back to TensorFlow client; we recommended you install the Cloud TPU client directly with pip install cloud-tpu-client.
Creating converter from 7 to 5
Creating converter from 5 to 7
Creating converter from 7 to 5
Creating converter from 5 to 7
Creating converter from 3 to 5
No training configuration found in the save file, so the model was *not* compiled. Compile it manually.
Falling back to TensorFlow client; we recommended you install the Cloud TPU client directly with pip install cloud-tpu-client.
Creating converter from 7 to 5
Creating converter from 5 to 7
Creating converter from 7 to 5
Creating converter from 5 to 7
Creating converter from 3 to 5
No training configuration found in the save file, so the model was *not* compiled. Compile it manually.
Watching for file changes with StatReloader
Falling back to TensorFlow client; we recommended you install the Cloud TPU client directly with pip install cloud-tpu-client.
Creating converter from 7 to 5
Creating converter from 5 to 7
Creating converter from 7 to 5
Creating converter from 5 to 7
Creating converter from 3 to 5
No training configuration found in the save file, so the model was *not* compiled. Compile it manually.
Falling back to TensorFlow client; we recommended you install the Cloud TPU client directly with pip install cloud-tpu-client.
Creating converter from 7 to 5
Creating converter from 5 to 7
Creating converter from 7 to 5
Creating converter from 5 to 7
Creating converter from 3 to 5
No training configuration found in the save file, so the model was *not* compiled. Compile it manually.
Falling back to TensorFlow client; we recommended you install the Cloud TPU client directly with pip install cloud-tpu-client.
Creating converter from 7 to 5
Creating converter from 5 to 7
Creating converter from 7 to 5
Creating converter from 5 to 7
Creating converter from 3 to 5
No training configuration found in the save file, so the model was *not* compiled. Compile it manually.
Falling back to TensorFlow client; we recommended you install the Cloud TPU client directly with pip install cloud-tpu-client.
Creating converter from 7 to 5
Creating converter from 5 to 7
Creating converter from 7 to 5
Creating converter from 5 to 7
Creating converter from 3 to 5
No training configuration found in the save file, so the model was *not* compiled. Compile it manually.
Falling back to TensorFlow client; we recommended you install the Cloud TPU client directly with pip install cloud-tpu-client.
Creating converter from 7 to 5
Creating converter from 5 to 7
Creating converter from 7 to 5
Creating converter from 5 to 7
Creating converter from 3 to 5
No training configuration found in the save file, so the model was *not* compiled. Compile it manually.
Falling back to TensorFlow client; we recommended you install the Cloud TPU client directly with pip install cloud-tpu-client.
Creating converter from 7 to 5
Creating converter from 5 to 7
Creating converter from 7 to 5
Creating converter from 5 to 7
Creating converter from 3 to 5
No training configuration found in the save file, so the model was *not* compiled. Compile it manually.
Watching for file changes with StatReloader
Importing BlpImagePlugin
Importing BmpImagePlugin
Importing BufrStubImagePlugin
Importing CurImagePlugin
Importing DcxImagePlugin
Importing DdsImagePlugin
Importing EpsImagePlugin
Importing FitsImagePlugin
Importing FliImagePlugin
Importing FpxImagePlugin
Image: failed to import FpxImagePlugin: No module named 'olefile'
Importing FtexImagePlugin
Importing GbrImagePlugin
Importing GifImagePlugin
Importing GribStubImagePlugin
Importing Hdf5StubImagePlugin
Importing IcnsImagePlugin
Importing IcoImagePlugin
Importing ImImagePlugin
Importing ImtImagePlugin
Importing IptcImagePlugin
Importing JpegImagePlugin
Importing Jpeg2KImagePlugin
Importing McIdasImagePlugin
Importing MicImagePlugin
Image: failed to import MicImagePlugin: No module named 'olefile'
Importing MpegImagePlugin
Importing MpoImagePlugin
Importing MspImagePlugin
Importing PalmImagePlugin
Importing PcdImagePlugin
Importing PcxImagePlugin
Importing PdfImagePlugin
Importing PixarImagePlugin
Importing PngImagePlugin
Importing PpmImagePlugin
Importing PsdImagePlugin
Importing QoiImagePlugin
Importing SgiImagePlugin
Importing SpiderImagePlugin
Importing SunImagePlugin
Importing TgaImagePlugin
Importing TiffImagePlugin
Importing WebPImagePlugin
Importing WmfImagePlugin
Importing XbmImagePlugin
Importing XpmImagePlugin
Importing XVThumbImagePlugin
Internal Server Error: /upload/
Traceback (most recent call last):
  File "C:\Users\lhu07\anaconda3\envs\big_project\Lib\site-packages\django\core\handlers\exception.py", line 55, in inner
    response = get_response(request)
               ^^^^^^^^^^^^^^^^^^^^^
  File "C:\Users\lhu07\anaconda3\envs\big_project\Lib\site-packages\django\core\handlers\base.py", line 197, in _get_response
    response = wrapped_callback(request, *callback_args, **callback_kwargs)
               ^^^^^^^^^^^^^^^^^^^^^^^^^^^^^^^^^^^^^^^^^^^^^^^^^^^^^^^^^^^^
  File "C:\Users\lhu07\anaconda3\envs\big_project\Lib\site-packages\django\contrib\auth\decorators.py", line 23, in _wrapper_view
    return view_func(request, *args, **kwargs)
           ^^^^^^^^^^^^^^^^^^^^^^^^^^^^^^^^^^^
  File "E:\빅프로젝트_34조\be_detect\bigproject28-1\detect\views.py", line 21, in upload_image_for_detection
    pest_info = Pest.objects.get(pest_id=pest_id)
                ^^^^^^^^^^^^^^^^^^^^^^^^^^^^^^^^^
  File "C:\Users\lhu07\anaconda3\envs\big_project\Lib\site-packages\django\db\models\manager.py", line 87, in manager_method
    return getattr(self.get_queryset(), name)(*args, **kwargs)
           ^^^^^^^^^^^^^^^^^^^^^^^^^^^^^^^^^^^^^^^^^^^^^^^^^^^
  File "C:\Users\lhu07\anaconda3\envs\big_project\Lib\site-packages\django\db\models\query.py", line 635, in get
    clone = self._chain() if self.query.combinator else self.filter(*args, **kwargs)
                                                        ^^^^^^^^^^^^^^^^^^^^^^^^^^^^
  File "C:\Users\lhu07\anaconda3\envs\big_project\Lib\site-packages\django\db\models\query.py", line 1476, in filter
    return self._filter_or_exclude(False, args, kwargs)
           ^^^^^^^^^^^^^^^^^^^^^^^^^^^^^^^^^^^^^^^^^^^^
  File "C:\Users\lhu07\anaconda3\envs\big_project\Lib\site-packages\django\db\models\query.py", line 1494, in _filter_or_exclude
    clone._filter_or_exclude_inplace(negate, args, kwargs)
  File "C:\Users\lhu07\anaconda3\envs\big_project\Lib\site-packages\django\db\models\query.py", line 1501, in _filter_or_exclude_inplace
    self._query.add_q(Q(*args, **kwargs))
  File "C:\Users\lhu07\anaconda3\envs\big_project\Lib\site-packages\django\db\models\sql\query.py", line 1613, in add_q
    clause, _ = self._add_q(q_object, self.used_aliases)
                ^^^^^^^^^^^^^^^^^^^^^^^^^^^^^^^^^^^^^^^^
  File "C:\Users\lhu07\anaconda3\envs\big_project\Lib\site-packages\django\db\models\sql\query.py", line 1645, in _add_q
    child_clause, needed_inner = self.build_filter(
                                 ^^^^^^^^^^^^^^^^^^
  File "C:\Users\lhu07\anaconda3\envs\big_project\Lib\site-packages\django\db\models\sql\query.py", line 1495, in build_filter
    lookups, parts, reffed_expression = self.solve_lookup_type(arg, summarize)
                                        ^^^^^^^^^^^^^^^^^^^^^^^^^^^^^^^^^^^^^^
  File "C:\Users\lhu07\anaconda3\envs\big_project\Lib\site-packages\django\db\models\sql\query.py", line 1307, in solve_lookup_type
    _, field, _, lookup_parts = self.names_to_path(lookup_splitted, self.get_meta())
                                ^^^^^^^^^^^^^^^^^^^^^^^^^^^^^^^^^^^^^^^^^^^^^^^^^^^^
  File "C:\Users\lhu07\anaconda3\envs\big_project\Lib\site-packages\django\db\models\sql\query.py", line 1772, in names_to_path
    raise FieldError(
django.core.exceptions.FieldError: Cannot resolve keyword 'pest_id' into field. Choices are: Occurrence_environment, Pesticide_name, Symptom_Description, detections, id, pest_name, prevention_methods
E:\빅프로젝트_34조\be_detect\bigproject28-1\detect\views.py changed, reloading.
Falling back to TensorFlow client; we recommended you install the Cloud TPU client directly with pip install cloud-tpu-client.
Creating converter from 7 to 5
Creating converter from 5 to 7
Creating converter from 7 to 5
Creating converter from 5 to 7
Creating converter from 3 to 5
No training configuration found in the save file, so the model was *not* compiled. Compile it manually.
Watching for file changes with StatReloader
Importing BlpImagePlugin
Importing BmpImagePlugin
Importing BufrStubImagePlugin
Importing CurImagePlugin
Importing DcxImagePlugin
Importing DdsImagePlugin
Importing EpsImagePlugin
Importing FitsImagePlugin
Importing FliImagePlugin
Importing FpxImagePlugin
Image: failed to import FpxImagePlugin: No module named 'olefile'
Importing FtexImagePlugin
Importing GbrImagePlugin
Importing GifImagePlugin
Importing GribStubImagePlugin
Importing Hdf5StubImagePlugin
Importing IcnsImagePlugin
Importing IcoImagePlugin
Importing ImImagePlugin
Importing ImtImagePlugin
Importing IptcImagePlugin
Importing JpegImagePlugin
Importing Jpeg2KImagePlugin
Importing McIdasImagePlugin
Importing MicImagePlugin
Image: failed to import MicImagePlugin: No module named 'olefile'
Importing MpegImagePlugin
Importing MpoImagePlugin
Importing MspImagePlugin
Importing PalmImagePlugin
Importing PcdImagePlugin
Importing PcxImagePlugin
Importing PdfImagePlugin
Importing PixarImagePlugin
Importing PngImagePlugin
Importing PpmImagePlugin
Importing PsdImagePlugin
Importing QoiImagePlugin
Importing SgiImagePlugin
Importing SpiderImagePlugin
Importing SunImagePlugin
Importing TgaImagePlugin
Importing TiffImagePlugin
Importing WebPImagePlugin
Importing WmfImagePlugin
Importing XbmImagePlugin
Importing XpmImagePlugin
Importing XVThumbImagePlugin
Internal Server Error: /upload/
Traceback (most recent call last):
  File "C:\Users\lhu07\anaconda3\envs\big_project\Lib\site-packages\django\db\backends\utils.py", line 105, in _execute
    return self.cursor.execute(sql, params)
           ^^^^^^^^^^^^^^^^^^^^^^^^^^^^^^^^
psycopg2.errors.UndefinedColumn: column detect_pest.Occurrence_environment does not exist
LINE 1: ...CT "detect_pest"."id", "detect_pest"."pest_name", "detect_pe...
                                                             ^
HINT:  Perhaps you meant to reference the column "detect_pest.occurrence_environment".


The above exception was the direct cause of the following exception:

Traceback (most recent call last):
  File "C:\Users\lhu07\anaconda3\envs\big_project\Lib\site-packages\django\core\handlers\exception.py", line 55, in inner
    response = get_response(request)
               ^^^^^^^^^^^^^^^^^^^^^
  File "C:\Users\lhu07\anaconda3\envs\big_project\Lib\site-packages\django\core\handlers\base.py", line 197, in _get_response
    response = wrapped_callback(request, *callback_args, **callback_kwargs)
               ^^^^^^^^^^^^^^^^^^^^^^^^^^^^^^^^^^^^^^^^^^^^^^^^^^^^^^^^^^^^
  File "C:\Users\lhu07\anaconda3\envs\big_project\Lib\site-packages\django\contrib\auth\decorators.py", line 23, in _wrapper_view
    return view_func(request, *args, **kwargs)
           ^^^^^^^^^^^^^^^^^^^^^^^^^^^^^^^^^^^
  File "E:\빅프로젝트_34조\be_detect\bigproject28-1\detect\views.py", line 24, in upload_image_for_detection
    pest_info = Pest.objects.get(id=pest_id)  # Changed from pest_id to id
                ^^^^^^^^^^^^^^^^^^^^^^^^^^^^
  File "C:\Users\lhu07\anaconda3\envs\big_project\Lib\site-packages\django\db\models\manager.py", line 87, in manager_method
    return getattr(self.get_queryset(), name)(*args, **kwargs)
           ^^^^^^^^^^^^^^^^^^^^^^^^^^^^^^^^^^^^^^^^^^^^^^^^^^^
  File "C:\Users\lhu07\anaconda3\envs\big_project\Lib\site-packages\django\db\models\query.py", line 645, in get
    num = len(clone)
          ^^^^^^^^^^
  File "C:\Users\lhu07\anaconda3\envs\big_project\Lib\site-packages\django\db\models\query.py", line 382, in __len__
    self._fetch_all()
  File "C:\Users\lhu07\anaconda3\envs\big_project\Lib\site-packages\django\db\models\query.py", line 1928, in _fetch_all
    self._result_cache = list(self._iterable_class(self))
                         ^^^^^^^^^^^^^^^^^^^^^^^^^^^^^^^^
  File "C:\Users\lhu07\anaconda3\envs\big_project\Lib\site-packages\django\db\models\query.py", line 91, in __iter__
    results = compiler.execute_sql(
              ^^^^^^^^^^^^^^^^^^^^^
  File "C:\Users\lhu07\anaconda3\envs\big_project\Lib\site-packages\django\db\models\sql\compiler.py", line 1562, in execute_sql
    cursor.execute(sql, params)
  File "C:\Users\lhu07\anaconda3\envs\big_project\Lib\site-packages\django\db\backends\utils.py", line 122, in execute
    return super().execute(sql, params)
           ^^^^^^^^^^^^^^^^^^^^^^^^^^^^
  File "C:\Users\lhu07\anaconda3\envs\big_project\Lib\site-packages\django\db\backends\utils.py", line 79, in execute
    return self._execute_with_wrappers(
           ^^^^^^^^^^^^^^^^^^^^^^^^^^^^
  File "C:\Users\lhu07\anaconda3\envs\big_project\Lib\site-packages\django\db\backends\utils.py", line 92, in _execute_with_wrappers
    return executor(sql, params, many, context)
           ^^^^^^^^^^^^^^^^^^^^^^^^^^^^^^^^^^^^
  File "C:\Users\lhu07\anaconda3\envs\big_project\Lib\site-packages\django\db\backends\utils.py", line 100, in _execute
    with self.db.wrap_database_errors:
  File "C:\Users\lhu07\anaconda3\envs\big_project\Lib\site-packages\django\db\utils.py", line 91, in __exit__
    raise dj_exc_value.with_traceback(traceback) from exc_value
  File "C:\Users\lhu07\anaconda3\envs\big_project\Lib\site-packages\django\db\backends\utils.py", line 105, in _execute
    return self.cursor.execute(sql, params)
           ^^^^^^^^^^^^^^^^^^^^^^^^^^^^^^^^
django.db.utils.ProgrammingError: column detect_pest.Occurrence_environment does not exist
LINE 1: ...CT "detect_pest"."id", "detect_pest"."pest_name", "detect_pe...
                                                             ^
HINT:  Perhaps you meant to reference the column "detect_pest.occurrence_environment".

Internal Server Error: /upload/
Traceback (most recent call last):
  File "C:\Users\lhu07\anaconda3\envs\big_project\Lib\site-packages\django\db\backends\utils.py", line 105, in _execute
    return self.cursor.execute(sql, params)
           ^^^^^^^^^^^^^^^^^^^^^^^^^^^^^^^^
psycopg2.errors.UndefinedColumn: column detect_pest.Occurrence_environment does not exist
LINE 1: ...CT "detect_pest"."id", "detect_pest"."pest_name", "detect_pe...
                                                             ^
HINT:  Perhaps you meant to reference the column "detect_pest.occurrence_environment".


The above exception was the direct cause of the following exception:

Traceback (most recent call last):
  File "C:\Users\lhu07\anaconda3\envs\big_project\Lib\site-packages\django\core\handlers\exception.py", line 55, in inner
    response = get_response(request)
               ^^^^^^^^^^^^^^^^^^^^^
  File "C:\Users\lhu07\anaconda3\envs\big_project\Lib\site-packages\django\core\handlers\base.py", line 197, in _get_response
    response = wrapped_callback(request, *callback_args, **callback_kwargs)
               ^^^^^^^^^^^^^^^^^^^^^^^^^^^^^^^^^^^^^^^^^^^^^^^^^^^^^^^^^^^^
  File "C:\Users\lhu07\anaconda3\envs\big_project\Lib\site-packages\django\contrib\auth\decorators.py", line 23, in _wrapper_view
    return view_func(request, *args, **kwargs)
           ^^^^^^^^^^^^^^^^^^^^^^^^^^^^^^^^^^^
  File "E:\빅프로젝트_34조\be_detect\bigproject28-1\detect\views.py", line 24, in upload_image_for_detection
    pest_info = Pest.objects.get(id=pest_id)  # Changed from pest_id to id
                ^^^^^^^^^^^^^^^^^^^^^^^^^^^^
  File "C:\Users\lhu07\anaconda3\envs\big_project\Lib\site-packages\django\db\models\manager.py", line 87, in manager_method
    return getattr(self.get_queryset(), name)(*args, **kwargs)
           ^^^^^^^^^^^^^^^^^^^^^^^^^^^^^^^^^^^^^^^^^^^^^^^^^^^
  File "C:\Users\lhu07\anaconda3\envs\big_project\Lib\site-packages\django\db\models\query.py", line 645, in get
    num = len(clone)
          ^^^^^^^^^^
  File "C:\Users\lhu07\anaconda3\envs\big_project\Lib\site-packages\django\db\models\query.py", line 382, in __len__
    self._fetch_all()
  File "C:\Users\lhu07\anaconda3\envs\big_project\Lib\site-packages\django\db\models\query.py", line 1928, in _fetch_all
    self._result_cache = list(self._iterable_class(self))
                         ^^^^^^^^^^^^^^^^^^^^^^^^^^^^^^^^
  File "C:\Users\lhu07\anaconda3\envs\big_project\Lib\site-packages\django\db\models\query.py", line 91, in __iter__
    results = compiler.execute_sql(
              ^^^^^^^^^^^^^^^^^^^^^
  File "C:\Users\lhu07\anaconda3\envs\big_project\Lib\site-packages\django\db\models\sql\compiler.py", line 1562, in execute_sql
    cursor.execute(sql, params)
  File "C:\Users\lhu07\anaconda3\envs\big_project\Lib\site-packages\django\db\backends\utils.py", line 122, in execute
    return super().execute(sql, params)
           ^^^^^^^^^^^^^^^^^^^^^^^^^^^^
  File "C:\Users\lhu07\anaconda3\envs\big_project\Lib\site-packages\django\db\backends\utils.py", line 79, in execute
    return self._execute_with_wrappers(
           ^^^^^^^^^^^^^^^^^^^^^^^^^^^^
  File "C:\Users\lhu07\anaconda3\envs\big_project\Lib\site-packages\django\db\backends\utils.py", line 92, in _execute_with_wrappers
    return executor(sql, params, many, context)
           ^^^^^^^^^^^^^^^^^^^^^^^^^^^^^^^^^^^^
  File "C:\Users\lhu07\anaconda3\envs\big_project\Lib\site-packages\django\db\backends\utils.py", line 100, in _execute
    with self.db.wrap_database_errors:
  File "C:\Users\lhu07\anaconda3\envs\big_project\Lib\site-packages\django\db\utils.py", line 91, in __exit__
    raise dj_exc_value.with_traceback(traceback) from exc_value
  File "C:\Users\lhu07\anaconda3\envs\big_project\Lib\site-packages\django\db\backends\utils.py", line 105, in _execute
    return self.cursor.execute(sql, params)
           ^^^^^^^^^^^^^^^^^^^^^^^^^^^^^^^^
django.db.utils.ProgrammingError: column detect_pest.Occurrence_environment does not exist
LINE 1: ...CT "detect_pest"."id", "detect_pest"."pest_name", "detect_pe...
                                                             ^
HINT:  Perhaps you meant to reference the column "detect_pest.occurrence_environment".

E:\빅프로젝트_34조\be_detect\bigproject28-1\detect\views.py changed, reloading.
Falling back to TensorFlow client; we recommended you install the Cloud TPU client directly with pip install cloud-tpu-client.
Creating converter from 7 to 5
Creating converter from 5 to 7
Creating converter from 7 to 5
Creating converter from 5 to 7
Creating converter from 3 to 5
No training configuration found in the save file, so the model was *not* compiled. Compile it manually.
Watching for file changes with StatReloader
E:\빅프로젝트_34조\be_detect\bigproject28-1\detect\models.py changed, reloading.
Falling back to TensorFlow client; we recommended you install the Cloud TPU client directly with pip install cloud-tpu-client.
Creating converter from 7 to 5
Creating converter from 5 to 7
Creating converter from 7 to 5
Creating converter from 5 to 7
Creating converter from 3 to 5
No training configuration found in the save file, so the model was *not* compiled. Compile it manually.
Falling back to TensorFlow client; we recommended you install the Cloud TPU client directly with pip install cloud-tpu-client.
Creating converter from 7 to 5
Creating converter from 5 to 7
Creating converter from 7 to 5
Creating converter from 5 to 7
Creating converter from 3 to 5
No training configuration found in the save file, so the model was *not* compiled. Compile it manually.
Falling back to TensorFlow client; we recommended you install the Cloud TPU client directly with pip install cloud-tpu-client.
Creating converter from 7 to 5
Creating converter from 5 to 7
Creating converter from 7 to 5
Creating converter from 5 to 7
Creating converter from 3 to 5
No training configuration found in the save file, so the model was *not* compiled. Compile it manually.
Falling back to TensorFlow client; we recommended you install the Cloud TPU client directly with pip install cloud-tpu-client.
Creating converter from 7 to 5
Creating converter from 5 to 7
Creating converter from 7 to 5
Creating converter from 5 to 7
Creating converter from 3 to 5
No training configuration found in the save file, so the model was *not* compiled. Compile it manually.
Falling back to TensorFlow client; we recommended you install the Cloud TPU client directly with pip install cloud-tpu-client.
Creating converter from 7 to 5
Creating converter from 5 to 7
Creating converter from 7 to 5
Creating converter from 5 to 7
Creating converter from 3 to 5
No training configuration found in the save file, so the model was *not* compiled. Compile it manually.
Falling back to TensorFlow client; we recommended you install the Cloud TPU client directly with pip install cloud-tpu-client.
Creating converter from 7 to 5
Creating converter from 5 to 7
Creating converter from 7 to 5
Creating converter from 5 to 7
Creating converter from 3 to 5
No training configuration found in the save file, so the model was *not* compiled. Compile it manually.
Falling back to TensorFlow client; we recommended you install the Cloud TPU client directly with pip install cloud-tpu-client.
Creating converter from 7 to 5
Creating converter from 5 to 7
Creating converter from 7 to 5
Creating converter from 5 to 7
Creating converter from 3 to 5
No training configuration found in the save file, so the model was *not* compiled. Compile it manually.
Watching for file changes with StatReloader
Importing BlpImagePlugin
Importing BmpImagePlugin
Importing BufrStubImagePlugin
Importing CurImagePlugin
Importing DcxImagePlugin
Importing DdsImagePlugin
Importing EpsImagePlugin
Importing FitsImagePlugin
Importing FliImagePlugin
Importing FpxImagePlugin
Image: failed to import FpxImagePlugin: No module named 'olefile'
Importing FtexImagePlugin
Importing GbrImagePlugin
Importing GifImagePlugin
Importing GribStubImagePlugin
Importing Hdf5StubImagePlugin
Importing IcnsImagePlugin
Importing IcoImagePlugin
Importing ImImagePlugin
Importing ImtImagePlugin
Importing IptcImagePlugin
Importing JpegImagePlugin
Importing Jpeg2KImagePlugin
Importing McIdasImagePlugin
Importing MicImagePlugin
Image: failed to import MicImagePlugin: No module named 'olefile'
Importing MpegImagePlugin
Importing MpoImagePlugin
Importing MspImagePlugin
Importing PalmImagePlugin
Importing PcdImagePlugin
Importing PcxImagePlugin
Importing PdfImagePlugin
Importing PixarImagePlugin
Importing PngImagePlugin
Importing PpmImagePlugin
Importing PsdImagePlugin
Importing QoiImagePlugin
Importing SgiImagePlugin
Importing SpiderImagePlugin
Importing SunImagePlugin
Importing TgaImagePlugin
Importing TiffImagePlugin
Importing WebPImagePlugin
Importing WmfImagePlugin
Importing XbmImagePlugin
Importing XpmImagePlugin
Importing XVThumbImagePlugin
Internal Server Error: /upload/
Traceback (most recent call last):
  File "E:\빅프로젝트_34조\be_detect\bigproject28-1\detect\views.py", line 24, in upload_image_for_detection
    pest_info = Pest.objects.get(id=pest_id)  # Changed from pest_id to id
                ^^^^^^^^^^^^^^^^^^^^^^^^^^^^
  File "C:\Users\lhu07\anaconda3\envs\big_project\Lib\site-packages\django\db\models\manager.py", line 87, in manager_method
    return getattr(self.get_queryset(), name)(*args, **kwargs)
           ^^^^^^^^^^^^^^^^^^^^^^^^^^^^^^^^^^^^^^^^^^^^^^^^^^^
  File "C:\Users\lhu07\anaconda3\envs\big_project\Lib\site-packages\django\db\models\query.py", line 649, in get
    raise self.model.DoesNotExist(
detect.models.Pest.DoesNotExist: Pest matching query does not exist.

During handling of the above exception, another exception occurred:

Traceback (most recent call last):
  File "C:\Users\lhu07\anaconda3\envs\big_project\Lib\site-packages\django\core\handlers\exception.py", line 55, in inner
    response = get_response(request)
               ^^^^^^^^^^^^^^^^^^^^^
  File "C:\Users\lhu07\anaconda3\envs\big_project\Lib\site-packages\django\core\handlers\base.py", line 197, in _get_response
    response = wrapped_callback(request, *callback_args, **callback_kwargs)
               ^^^^^^^^^^^^^^^^^^^^^^^^^^^^^^^^^^^^^^^^^^^^^^^^^^^^^^^^^^^^
  File "C:\Users\lhu07\anaconda3\envs\big_project\Lib\site-packages\django\contrib\auth\decorators.py", line 23, in _wrapper_view
    return view_func(request, *args, **kwargs)
           ^^^^^^^^^^^^^^^^^^^^^^^^^^^^^^^^^^^
  File "E:\빅프로젝트_34조\be_detect\bigproject28-1\detect\views.py", line 26, in upload_image_for_detection
    return render(request, 'result.html', {
           ^^^^^^^^^^^^^^^^^^^^^^^^^^^^^^^^
  File "C:\Users\lhu07\anaconda3\envs\big_project\Lib\site-packages\django\shortcuts.py", line 25, in render
    content = loader.render_to_string(template_name, context, request, using=using)
              ^^^^^^^^^^^^^^^^^^^^^^^^^^^^^^^^^^^^^^^^^^^^^^^^^^^^^^^^^^^^^^^^^^^^^
  File "C:\Users\lhu07\anaconda3\envs\big_project\Lib\site-packages\django\template\loader.py", line 62, in render_to_string
    return template.render(context, request)
           ^^^^^^^^^^^^^^^^^^^^^^^^^^^^^^^^^
  File "C:\Users\lhu07\anaconda3\envs\big_project\Lib\site-packages\django\template\backends\django.py", line 61, in render
    return self.template.render(context)
           ^^^^^^^^^^^^^^^^^^^^^^^^^^^^^
  File "C:\Users\lhu07\anaconda3\envs\big_project\Lib\site-packages\django\template\base.py", line 171, in render
    return self._render(context)
           ^^^^^^^^^^^^^^^^^^^^^
  File "C:\Users\lhu07\anaconda3\envs\big_project\Lib\site-packages\django\template\base.py", line 163, in _render
    return self.nodelist.render(context)
           ^^^^^^^^^^^^^^^^^^^^^^^^^^^^^
  File "C:\Users\lhu07\anaconda3\envs\big_project\Lib\site-packages\django\template\base.py", line 1000, in render
    return SafeString("".join([node.render_annotated(context) for node in self]))
                              ^^^^^^^^^^^^^^^^^^^^^^^^^^^^^^^^^^^^^^^^^^^^^^^^^
  File "C:\Users\lhu07\anaconda3\envs\big_project\Lib\site-packages\django\template\base.py", line 1000, in <listcomp>
    return SafeString("".join([node.render_annotated(context) for node in self]))
                               ^^^^^^^^^^^^^^^^^^^^^^^^^^^^^^
  File "C:\Users\lhu07\anaconda3\envs\big_project\Lib\site-packages\django\template\base.py", line 961, in render_annotated
    return self.render(context)
           ^^^^^^^^^^^^^^^^^^^^
  File "C:\Users\lhu07\anaconda3\envs\big_project\Lib\site-packages\django\template\defaulttags.py", line 479, in render
    url = reverse(view_name, args=args, kwargs=kwargs, current_app=current_app)
          ^^^^^^^^^^^^^^^^^^^^^^^^^^^^^^^^^^^^^^^^^^^^^^^^^^^^^^^^^^^^^^^^^^^^^
  File "C:\Users\lhu07\anaconda3\envs\big_project\Lib\site-packages\django\urls\base.py", line 88, in reverse
    return resolver._reverse_with_prefix(view, prefix, *args, **kwargs)
           ^^^^^^^^^^^^^^^^^^^^^^^^^^^^^^^^^^^^^^^^^^^^^^^^^^^^^^^^^^^^
  File "C:\Users\lhu07\anaconda3\envs\big_project\Lib\site-packages\django\urls\resolvers.py", line 851, in _reverse_with_prefix
    raise NoReverseMatch(msg)
django.urls.exceptions.NoReverseMatch: Reverse for 'upload_image_for_detection' not found. 'upload_image_for_detection' is not a valid view function or pattern name.
E:\빅프로젝트_34조\be_detect\bigproject28-1\detect\views.py changed, reloading.
Falling back to TensorFlow client; we recommended you install the Cloud TPU client directly with pip install cloud-tpu-client.
Creating converter from 7 to 5
Creating converter from 5 to 7
Creating converter from 7 to 5
Creating converter from 5 to 7
Creating converter from 3 to 5
No training configuration found in the save file, so the model was *not* compiled. Compile it manually.
Watching for file changes with StatReloader
Importing BlpImagePlugin
Importing BmpImagePlugin
Importing BufrStubImagePlugin
Importing CurImagePlugin
Importing DcxImagePlugin
Importing DdsImagePlugin
Importing EpsImagePlugin
Importing FitsImagePlugin
Importing FliImagePlugin
Importing FpxImagePlugin
Image: failed to import FpxImagePlugin: No module named 'olefile'
Importing FtexImagePlugin
Importing GbrImagePlugin
Importing GifImagePlugin
Importing GribStubImagePlugin
Importing Hdf5StubImagePlugin
Importing IcnsImagePlugin
Importing IcoImagePlugin
Importing ImImagePlugin
Importing ImtImagePlugin
Importing IptcImagePlugin
Importing JpegImagePlugin
Importing Jpeg2KImagePlugin
Importing McIdasImagePlugin
Importing MicImagePlugin
Image: failed to import MicImagePlugin: No module named 'olefile'
Importing MpegImagePlugin
Importing MpoImagePlugin
Importing MspImagePlugin
Importing PalmImagePlugin
Importing PcdImagePlugin
Importing PcxImagePlugin
Importing PdfImagePlugin
Importing PixarImagePlugin
Importing PngImagePlugin
Importing PpmImagePlugin
Importing PsdImagePlugin
Importing QoiImagePlugin
Importing SgiImagePlugin
Importing SpiderImagePlugin
Importing SunImagePlugin
Importing TgaImagePlugin
Importing TiffImagePlugin
Importing WebPImagePlugin
Importing WmfImagePlugin
Importing XbmImagePlugin
Importing XpmImagePlugin
Importing XVThumbImagePlugin
Internal Server Error: /upload/
Traceback (most recent call last):
  File "C:\Users\lhu07\anaconda3\envs\big_project\Lib\site-packages\django\db\backends\utils.py", line 105, in _execute
    return self.cursor.execute(sql, params)
           ^^^^^^^^^^^^^^^^^^^^^^^^^^^^^^^^
psycopg2.errors.UndefinedColumn: column "image_url" of relation "detect_pestdetection" does not exist
LINE 1: ...ct_pestdetection" ("user_id", "pest_id", "image", "image_url...
                                                             ^


The above exception was the direct cause of the following exception:

Traceback (most recent call last):
  File "C:\Users\lhu07\anaconda3\envs\big_project\Lib\site-packages\django\core\handlers\exception.py", line 55, in inner
    response = get_response(request)
               ^^^^^^^^^^^^^^^^^^^^^
  File "C:\Users\lhu07\anaconda3\envs\big_project\Lib\site-packages\django\core\handlers\base.py", line 197, in _get_response
    response = wrapped_callback(request, *callback_args, **callback_kwargs)
               ^^^^^^^^^^^^^^^^^^^^^^^^^^^^^^^^^^^^^^^^^^^^^^^^^^^^^^^^^^^^
  File "C:\Users\lhu07\anaconda3\envs\big_project\Lib\site-packages\django\contrib\auth\decorators.py", line 23, in _wrapper_view
    return view_func(request, *args, **kwargs)
           ^^^^^^^^^^^^^^^^^^^^^^^^^^^^^^^^^^^
  File "E:\빅프로젝트_34조\be_detect\bigproject28-1\detect\views.py", line 40, in upload_image_for_detection
    detection.save()
  File "C:\Users\lhu07\anaconda3\envs\big_project\Lib\site-packages\django\db\models\base.py", line 822, in save
    self.save_base(
  File "C:\Users\lhu07\anaconda3\envs\big_project\Lib\site-packages\django\db\models\base.py", line 909, in save_base
    updated = self._save_table(
              ^^^^^^^^^^^^^^^^^
  File "C:\Users\lhu07\anaconda3\envs\big_project\Lib\site-packages\django\db\models\base.py", line 1071, in _save_table
    results = self._do_insert(
              ^^^^^^^^^^^^^^^^
  File "C:\Users\lhu07\anaconda3\envs\big_project\Lib\site-packages\django\db\models\base.py", line 1112, in _do_insert
    return manager._insert(
           ^^^^^^^^^^^^^^^^
  File "C:\Users\lhu07\anaconda3\envs\big_project\Lib\site-packages\django\db\models\manager.py", line 87, in manager_method
    return getattr(self.get_queryset(), name)(*args, **kwargs)
           ^^^^^^^^^^^^^^^^^^^^^^^^^^^^^^^^^^^^^^^^^^^^^^^^^^^
  File "C:\Users\lhu07\anaconda3\envs\big_project\Lib\site-packages\django\db\models\query.py", line 1847, in _insert
    return query.get_compiler(using=using).execute_sql(returning_fields)
           ^^^^^^^^^^^^^^^^^^^^^^^^^^^^^^^^^^^^^^^^^^^^^^^^^^^^^^^^^^^^^
  File "C:\Users\lhu07\anaconda3\envs\big_project\Lib\site-packages\django\db\models\sql\compiler.py", line 1823, in execute_sql
    cursor.execute(sql, params)
  File "C:\Users\lhu07\anaconda3\envs\big_project\Lib\site-packages\django\db\backends\utils.py", line 122, in execute
    return super().execute(sql, params)
           ^^^^^^^^^^^^^^^^^^^^^^^^^^^^
  File "C:\Users\lhu07\anaconda3\envs\big_project\Lib\site-packages\django\db\backends\utils.py", line 79, in execute
    return self._execute_with_wrappers(
           ^^^^^^^^^^^^^^^^^^^^^^^^^^^^
  File "C:\Users\lhu07\anaconda3\envs\big_project\Lib\site-packages\django\db\backends\utils.py", line 92, in _execute_with_wrappers
    return executor(sql, params, many, context)
           ^^^^^^^^^^^^^^^^^^^^^^^^^^^^^^^^^^^^
  File "C:\Users\lhu07\anaconda3\envs\big_project\Lib\site-packages\django\db\backends\utils.py", line 100, in _execute
    with self.db.wrap_database_errors:
  File "C:\Users\lhu07\anaconda3\envs\big_project\Lib\site-packages\django\db\utils.py", line 91, in __exit__
    raise dj_exc_value.with_traceback(traceback) from exc_value
  File "C:\Users\lhu07\anaconda3\envs\big_project\Lib\site-packages\django\db\backends\utils.py", line 105, in _execute
    return self.cursor.execute(sql, params)
           ^^^^^^^^^^^^^^^^^^^^^^^^^^^^^^^^
django.db.utils.ProgrammingError: column "image_url" of relation "detect_pestdetection" does not exist
LINE 1: ...ct_pestdetection" ("user_id", "pest_id", "image", "image_url...
                                                             ^

Internal Server Error: /upload/
Traceback (most recent call last):
  File "C:\Users\lhu07\anaconda3\envs\big_project\Lib\site-packages\django\db\backends\utils.py", line 105, in _execute
    return self.cursor.execute(sql, params)
           ^^^^^^^^^^^^^^^^^^^^^^^^^^^^^^^^
psycopg2.errors.UndefinedColumn: column "image_url" of relation "detect_pestdetection" does not exist
LINE 1: ...ct_pestdetection" ("user_id", "pest_id", "image", "image_url...
                                                             ^


The above exception was the direct cause of the following exception:

Traceback (most recent call last):
  File "C:\Users\lhu07\anaconda3\envs\big_project\Lib\site-packages\django\core\handlers\exception.py", line 55, in inner
    response = get_response(request)
               ^^^^^^^^^^^^^^^^^^^^^
  File "C:\Users\lhu07\anaconda3\envs\big_project\Lib\site-packages\django\core\handlers\base.py", line 197, in _get_response
    response = wrapped_callback(request, *callback_args, **callback_kwargs)
               ^^^^^^^^^^^^^^^^^^^^^^^^^^^^^^^^^^^^^^^^^^^^^^^^^^^^^^^^^^^^
  File "C:\Users\lhu07\anaconda3\envs\big_project\Lib\site-packages\django\contrib\auth\decorators.py", line 23, in _wrapper_view
    return view_func(request, *args, **kwargs)
           ^^^^^^^^^^^^^^^^^^^^^^^^^^^^^^^^^^^
  File "E:\빅프로젝트_34조\be_detect\bigproject28-1\detect\views.py", line 40, in upload_image_for_detection
    detection.save()
  File "C:\Users\lhu07\anaconda3\envs\big_project\Lib\site-packages\django\db\models\base.py", line 822, in save
    self.save_base(
  File "C:\Users\lhu07\anaconda3\envs\big_project\Lib\site-packages\django\db\models\base.py", line 909, in save_base
    updated = self._save_table(
              ^^^^^^^^^^^^^^^^^
  File "C:\Users\lhu07\anaconda3\envs\big_project\Lib\site-packages\django\db\models\base.py", line 1071, in _save_table
    results = self._do_insert(
              ^^^^^^^^^^^^^^^^
  File "C:\Users\lhu07\anaconda3\envs\big_project\Lib\site-packages\django\db\models\base.py", line 1112, in _do_insert
    return manager._insert(
           ^^^^^^^^^^^^^^^^
  File "C:\Users\lhu07\anaconda3\envs\big_project\Lib\site-packages\django\db\models\manager.py", line 87, in manager_method
    return getattr(self.get_queryset(), name)(*args, **kwargs)
           ^^^^^^^^^^^^^^^^^^^^^^^^^^^^^^^^^^^^^^^^^^^^^^^^^^^
  File "C:\Users\lhu07\anaconda3\envs\big_project\Lib\site-packages\django\db\models\query.py", line 1847, in _insert
    return query.get_compiler(using=using).execute_sql(returning_fields)
           ^^^^^^^^^^^^^^^^^^^^^^^^^^^^^^^^^^^^^^^^^^^^^^^^^^^^^^^^^^^^^
  File "C:\Users\lhu07\anaconda3\envs\big_project\Lib\site-packages\django\db\models\sql\compiler.py", line 1823, in execute_sql
    cursor.execute(sql, params)
  File "C:\Users\lhu07\anaconda3\envs\big_project\Lib\site-packages\django\db\backends\utils.py", line 122, in execute
    return super().execute(sql, params)
           ^^^^^^^^^^^^^^^^^^^^^^^^^^^^
  File "C:\Users\lhu07\anaconda3\envs\big_project\Lib\site-packages\django\db\backends\utils.py", line 79, in execute
    return self._execute_with_wrappers(
           ^^^^^^^^^^^^^^^^^^^^^^^^^^^^
  File "C:\Users\lhu07\anaconda3\envs\big_project\Lib\site-packages\django\db\backends\utils.py", line 92, in _execute_with_wrappers
    return executor(sql, params, many, context)
           ^^^^^^^^^^^^^^^^^^^^^^^^^^^^^^^^^^^^
  File "C:\Users\lhu07\anaconda3\envs\big_project\Lib\site-packages\django\db\backends\utils.py", line 100, in _execute
    with self.db.wrap_database_errors:
  File "C:\Users\lhu07\anaconda3\envs\big_project\Lib\site-packages\django\db\utils.py", line 91, in __exit__
    raise dj_exc_value.with_traceback(traceback) from exc_value
  File "C:\Users\lhu07\anaconda3\envs\big_project\Lib\site-packages\django\db\backends\utils.py", line 105, in _execute
    return self.cursor.execute(sql, params)
           ^^^^^^^^^^^^^^^^^^^^^^^^^^^^^^^^
django.db.utils.ProgrammingError: column "image_url" of relation "detect_pestdetection" does not exist
LINE 1: ...ct_pestdetection" ("user_id", "pest_id", "image", "image_url...
                                                             ^

E:\빅프로젝트_34조\be_detect\bigproject28-1\detect\models.py changed, reloading.
Falling back to TensorFlow client; we recommended you install the Cloud TPU client directly with pip install cloud-tpu-client.
Creating converter from 7 to 5
Creating converter from 5 to 7
Creating converter from 7 to 5
Creating converter from 5 to 7
Creating converter from 3 to 5
No training configuration found in the save file, so the model was *not* compiled. Compile it manually.
Falling back to TensorFlow client; we recommended you install the Cloud TPU client directly with pip install cloud-tpu-client.
Creating converter from 7 to 5
Creating converter from 5 to 7
Creating converter from 7 to 5
Creating converter from 5 to 7
Creating converter from 3 to 5
No training configuration found in the save file, so the model was *not* compiled. Compile it manually.
Falling back to TensorFlow client; we recommended you install the Cloud TPU client directly with pip install cloud-tpu-client.
Creating converter from 7 to 5
Creating converter from 5 to 7
Creating converter from 7 to 5
Creating converter from 5 to 7
Creating converter from 3 to 5
No training configuration found in the save file, so the model was *not* compiled. Compile it manually.
Falling back to TensorFlow client; we recommended you install the Cloud TPU client directly with pip install cloud-tpu-client.
Creating converter from 7 to 5
Creating converter from 5 to 7
Creating converter from 7 to 5
Creating converter from 5 to 7
Creating converter from 3 to 5
No training configuration found in the save file, so the model was *not* compiled. Compile it manually.
Falling back to TensorFlow client; we recommended you install the Cloud TPU client directly with pip install cloud-tpu-client.
Creating converter from 7 to 5
Creating converter from 5 to 7
Creating converter from 7 to 5
Creating converter from 5 to 7
Creating converter from 3 to 5
No training configuration found in the save file, so the model was *not* compiled. Compile it manually.
Watching for file changes with StatReloader
Importing BlpImagePlugin
Importing BmpImagePlugin
Importing BufrStubImagePlugin
Importing CurImagePlugin
Importing DcxImagePlugin
Importing DdsImagePlugin
Importing EpsImagePlugin
Importing FitsImagePlugin
Importing FliImagePlugin
Importing FpxImagePlugin
Image: failed to import FpxImagePlugin: No module named 'olefile'
Importing FtexImagePlugin
Importing GbrImagePlugin
Importing GifImagePlugin
Importing GribStubImagePlugin
Importing Hdf5StubImagePlugin
Importing IcnsImagePlugin
Importing IcoImagePlugin
Importing ImImagePlugin
Importing ImtImagePlugin
Importing IptcImagePlugin
Importing JpegImagePlugin
Importing Jpeg2KImagePlugin
Importing McIdasImagePlugin
Importing MicImagePlugin
Image: failed to import MicImagePlugin: No module named 'olefile'
Importing MpegImagePlugin
Importing MpoImagePlugin
Importing MspImagePlugin
Importing PalmImagePlugin
Importing PcdImagePlugin
Importing PcxImagePlugin
Importing PdfImagePlugin
Importing PixarImagePlugin
Importing PngImagePlugin
Importing PpmImagePlugin
Importing PsdImagePlugin
Importing QoiImagePlugin
Importing SgiImagePlugin
Importing SpiderImagePlugin
Importing SunImagePlugin
Importing TgaImagePlugin
Importing TiffImagePlugin
Importing WebPImagePlugin
Importing WmfImagePlugin
Importing XbmImagePlugin
Importing XpmImagePlugin
Importing XVThumbImagePlugin
Internal Server Error: /upload/
Traceback (most recent call last):
  File "C:\Users\lhu07\anaconda3\envs\big_project\Lib\site-packages\django\core\handlers\exception.py", line 55, in inner
    response = get_response(request)
               ^^^^^^^^^^^^^^^^^^^^^
  File "C:\Users\lhu07\anaconda3\envs\big_project\Lib\site-packages\django\core\handlers\base.py", line 197, in _get_response
    response = wrapped_callback(request, *callback_args, **callback_kwargs)
               ^^^^^^^^^^^^^^^^^^^^^^^^^^^^^^^^^^^^^^^^^^^^^^^^^^^^^^^^^^^^
  File "C:\Users\lhu07\anaconda3\envs\big_project\Lib\site-packages\django\contrib\auth\decorators.py", line 23, in _wrapper_view
    return view_func(request, *args, **kwargs)
           ^^^^^^^^^^^^^^^^^^^^^^^^^^^^^^^^^^^
  File "E:\빅프로젝트_34조\be_detect\bigproject28-1\detect\views.py", line 46, in upload_image_for_detection
    'threat_level': pest_info.threat_level,
                    ^^^^^^^^^^^^^^^^^^^^^^
AttributeError: 'Pest' object has no attribute 'threat_level'
Internal Server Error: /upload/
Traceback (most recent call last):
  File "C:\Users\lhu07\anaconda3\envs\big_project\Lib\site-packages\django\core\handlers\exception.py", line 55, in inner
    response = get_response(request)
               ^^^^^^^^^^^^^^^^^^^^^
  File "C:\Users\lhu07\anaconda3\envs\big_project\Lib\site-packages\django\core\handlers\base.py", line 197, in _get_response
    response = wrapped_callback(request, *callback_args, **callback_kwargs)
               ^^^^^^^^^^^^^^^^^^^^^^^^^^^^^^^^^^^^^^^^^^^^^^^^^^^^^^^^^^^^
  File "C:\Users\lhu07\anaconda3\envs\big_project\Lib\site-packages\django\contrib\auth\decorators.py", line 23, in _wrapper_view
    return view_func(request, *args, **kwargs)
           ^^^^^^^^^^^^^^^^^^^^^^^^^^^^^^^^^^^
  File "E:\빅프로젝트_34조\be_detect\bigproject28-1\detect\views.py", line 46, in upload_image_for_detection
    'threat_level': pest_info.threat_level,
                    ^^^^^^^^^^^^^^^^^^^^^^
AttributeError: 'Pest' object has no attribute 'threat_level'
Internal Server Error: /upload/
Traceback (most recent call last):
  File "C:\Users\lhu07\anaconda3\envs\big_project\Lib\site-packages\django\core\handlers\exception.py", line 55, in inner
    response = get_response(request)
               ^^^^^^^^^^^^^^^^^^^^^
  File "C:\Users\lhu07\anaconda3\envs\big_project\Lib\site-packages\django\core\handlers\base.py", line 197, in _get_response
    response = wrapped_callback(request, *callback_args, **callback_kwargs)
               ^^^^^^^^^^^^^^^^^^^^^^^^^^^^^^^^^^^^^^^^^^^^^^^^^^^^^^^^^^^^
  File "C:\Users\lhu07\anaconda3\envs\big_project\Lib\site-packages\django\contrib\auth\decorators.py", line 23, in _wrapper_view
    return view_func(request, *args, **kwargs)
           ^^^^^^^^^^^^^^^^^^^^^^^^^^^^^^^^^^^
  File "E:\빅프로젝트_34조\be_detect\bigproject28-1\detect\views.py", line 46, in upload_image_for_detection
    'threat_level': pest_info.threat_level,
                    ^^^^^^^^^^^^^^^^^^^^^^
AttributeError: 'Pest' object has no attribute 'threat_level'
E:\빅프로젝트_34조\be_detect\bigproject28-1\detect\views.py changed, reloading.
Falling back to TensorFlow client; we recommended you install the Cloud TPU client directly with pip install cloud-tpu-client.
Creating converter from 7 to 5
Creating converter from 5 to 7
Creating converter from 7 to 5
Creating converter from 5 to 7
Creating converter from 3 to 5
No training configuration found in the save file, so the model was *not* compiled. Compile it manually.
Watching for file changes with StatReloader
Importing BlpImagePlugin
Importing BmpImagePlugin
Importing BufrStubImagePlugin
Importing CurImagePlugin
Importing DcxImagePlugin
Importing DdsImagePlugin
Importing EpsImagePlugin
Importing FitsImagePlugin
Importing FliImagePlugin
Importing FpxImagePlugin
Image: failed to import FpxImagePlugin: No module named 'olefile'
Importing FtexImagePlugin
Importing GbrImagePlugin
Importing GifImagePlugin
Importing GribStubImagePlugin
Importing Hdf5StubImagePlugin
Importing IcnsImagePlugin
Importing IcoImagePlugin
Importing ImImagePlugin
Importing ImtImagePlugin
Importing IptcImagePlugin
Importing JpegImagePlugin
Importing Jpeg2KImagePlugin
Importing McIdasImagePlugin
Importing MicImagePlugin
Image: failed to import MicImagePlugin: No module named 'olefile'
Importing MpegImagePlugin
Importing MpoImagePlugin
Importing MspImagePlugin
Importing PalmImagePlugin
Importing PcdImagePlugin
Importing PcxImagePlugin
Importing PdfImagePlugin
Importing PixarImagePlugin
Importing PngImagePlugin
Importing PpmImagePlugin
Importing PsdImagePlugin
Importing QoiImagePlugin
Importing SgiImagePlugin
Importing SpiderImagePlugin
Importing SunImagePlugin
Importing TgaImagePlugin
Importing TiffImagePlugin
Importing WebPImagePlugin
Importing WmfImagePlugin
Importing XbmImagePlugin
Importing XpmImagePlugin
Importing XVThumbImagePlugin
Internal Server Error: /upload/
Traceback (most recent call last):
  File "C:\Users\lhu07\anaconda3\envs\big_project\Lib\site-packages\django\core\handlers\exception.py", line 55, in inner
    response = get_response(request)
               ^^^^^^^^^^^^^^^^^^^^^
  File "C:\Users\lhu07\anaconda3\envs\big_project\Lib\site-packages\django\core\handlers\base.py", line 197, in _get_response
    response = wrapped_callback(request, *callback_args, **callback_kwargs)
               ^^^^^^^^^^^^^^^^^^^^^^^^^^^^^^^^^^^^^^^^^^^^^^^^^^^^^^^^^^^^
  File "C:\Users\lhu07\anaconda3\envs\big_project\Lib\site-packages\django\contrib\auth\decorators.py", line 23, in _wrapper_view
    return view_func(request, *args, **kwargs)
           ^^^^^^^^^^^^^^^^^^^^^^^^^^^^^^^^^^^
  File "E:\빅프로젝트_34조\be_detect\bigproject28-1\detect\views.py", line 53, in upload_image_for_detection
    return render(request, 'result.html', context)
           ^^^^^^^^^^^^^^^^^^^^^^^^^^^^^^^^^^^^^^^
  File "C:\Users\lhu07\anaconda3\envs\big_project\Lib\site-packages\django\shortcuts.py", line 25, in render
    content = loader.render_to_string(template_name, context, request, using=using)
              ^^^^^^^^^^^^^^^^^^^^^^^^^^^^^^^^^^^^^^^^^^^^^^^^^^^^^^^^^^^^^^^^^^^^^
  File "C:\Users\lhu07\anaconda3\envs\big_project\Lib\site-packages\django\template\loader.py", line 62, in render_to_string
    return template.render(context, request)
           ^^^^^^^^^^^^^^^^^^^^^^^^^^^^^^^^^
  File "C:\Users\lhu07\anaconda3\envs\big_project\Lib\site-packages\django\template\backends\django.py", line 61, in render
    return self.template.render(context)
           ^^^^^^^^^^^^^^^^^^^^^^^^^^^^^
  File "C:\Users\lhu07\anaconda3\envs\big_project\Lib\site-packages\django\template\base.py", line 171, in render
    return self._render(context)
           ^^^^^^^^^^^^^^^^^^^^^
  File "C:\Users\lhu07\anaconda3\envs\big_project\Lib\site-packages\django\template\base.py", line 163, in _render
    return self.nodelist.render(context)
           ^^^^^^^^^^^^^^^^^^^^^^^^^^^^^
  File "C:\Users\lhu07\anaconda3\envs\big_project\Lib\site-packages\django\template\base.py", line 1000, in render
    return SafeString("".join([node.render_annotated(context) for node in self]))
                              ^^^^^^^^^^^^^^^^^^^^^^^^^^^^^^^^^^^^^^^^^^^^^^^^^
  File "C:\Users\lhu07\anaconda3\envs\big_project\Lib\site-packages\django\template\base.py", line 1000, in <listcomp>
    return SafeString("".join([node.render_annotated(context) for node in self]))
                               ^^^^^^^^^^^^^^^^^^^^^^^^^^^^^^
  File "C:\Users\lhu07\anaconda3\envs\big_project\Lib\site-packages\django\template\base.py", line 961, in render_annotated
    return self.render(context)
           ^^^^^^^^^^^^^^^^^^^^
  File "C:\Users\lhu07\anaconda3\envs\big_project\Lib\site-packages\django\template\defaulttags.py", line 479, in render
    url = reverse(view_name, args=args, kwargs=kwargs, current_app=current_app)
          ^^^^^^^^^^^^^^^^^^^^^^^^^^^^^^^^^^^^^^^^^^^^^^^^^^^^^^^^^^^^^^^^^^^^^
  File "C:\Users\lhu07\anaconda3\envs\big_project\Lib\site-packages\django\urls\base.py", line 88, in reverse
    return resolver._reverse_with_prefix(view, prefix, *args, **kwargs)
           ^^^^^^^^^^^^^^^^^^^^^^^^^^^^^^^^^^^^^^^^^^^^^^^^^^^^^^^^^^^^
  File "C:\Users\lhu07\anaconda3\envs\big_project\Lib\site-packages\django\urls\resolvers.py", line 851, in _reverse_with_prefix
    raise NoReverseMatch(msg)
django.urls.exceptions.NoReverseMatch: Reverse for 'upload_image_for_detection' not found. 'upload_image_for_detection' is not a valid view function or pattern name.
